<?xml version="1.0" ?>
<!-- =================================================================================== -->
<!-- |    This document was autogenerated by xacro from src/ur5_vision_pick/ur5_description/urdf//ur5_hitbot_with_ilc_platform.urdf.xacro | -->
<!-- |    EDITING THIS FILE BY HAND IS NOT RECOMMENDED                                 | -->
<!-- =================================================================================== -->
<!--
Copyright (c) 2018 Intel Corporation

Licensed under the Apache License, Version 2.0 (the "License");
you may not use this file except in compliance with the License.
You may obtain a copy of the License at

     http://www.apache.org/licenses/LICENSE-2.0

Unless required by applicable law or agreed to in writing, software
distributed under the License is distributed on an "AS IS" BASIS,
WITHOUT WARRANTIES OR CONDITIONS OF ANY KIND, either express or implied.
See the License for the specific language governing permissions and
limitations under the License.
-->
<robot name="ur5_hitbot_with_ilc_platform" xmlns:xacro="http://ros.org/wiki/xacro">
  <gazebo>
    <plugin filename="libgazebo_ros_control.so" name="ros_control">
      <!--robotNamespace>/</robotNamespace-->
      <!--robotSimType>gazebo_ros_control/DefaultRobotHWSim</robotSimType-->
    </plugin>
    <!--
    <plugin name="gazebo_ros_power_monitor_controller" filename="libgazebo_ros_power_monitor.so">
      <alwaysOn>true</alwaysOn>
      <updateRate>1.0</updateRate>
      <timeout>5</timeout>
      <powerStateTopic>power_state</powerStateTopic>
      <powerStateRate>10.0</powerStateRate>
      <fullChargeCapacity>87.78</fullChargeCapacity>     
      <dischargeRate>-474</dischargeRate>
      <chargeRate>525</chargeRate>
      <dischargeVoltage>15.52</dischargeVoltage>
      <chargeVoltage>16.41</chargeVoltage>
    </plugin>
-->
  </gazebo>
  <link name="platform_base"/>
  <link name="beam_support_front_right">
    <visual>
      <origin rpy="0 0 0" xyz="0 0 0"/>
      <geometry>
        <box size="0.08 0.08 0.32"/>
      </geometry>
      <material name="grey_blue">
        <color rgba="0.3 0.3 0.7 1.0"/>
      </material>
    </visual>
    <collision>
      <origin rpy="0 0 0" xyz="0 0 0"/>
      <geometry>
        <box size="0.08 0.08 0.32"/>
      </geometry>
    </collision>
  </link>
  <joint name="platform_base_beam_support_front_right_joint" type="fixed">
    <parent link="platform_base"/>
    <child link="beam_support_front_right"/>
    <origin rpy="0.0 0.0 0.0" xyz="-0.31                             -0.53                             0.275"/>
  </joint>
  <!-- Individual link colouring still needed in Gazebo 2.x -->
  <gazebo reference="beam_support_front_right">
    <material>Gazebo/Blue</material>
  </gazebo>
  <link name="beam_support_front_left">
    <visual>
      <origin rpy="0 0 0" xyz="0 0 0"/>
      <geometry>
        <box size="0.08 0.08 0.32"/>
      </geometry>
      <material name="grey_blue">
        <color rgba="0.3 0.3 0.7 1.0"/>
      </material>
    </visual>
    <collision>
      <origin rpy="0 0 0" xyz="0 0 0"/>
      <geometry>
        <box size="0.08 0.08 0.32"/>
      </geometry>
    </collision>
  </link>
  <joint name="platform_base_beam_support_front_left_joint" type="fixed">
    <parent link="platform_base"/>
    <child link="beam_support_front_left"/>
    <origin rpy="0.0 0.0 0.0" xyz="0.31                             -0.53                             0.275"/>
  </joint>
  <!-- Individual link colouring still needed in Gazebo 2.x -->
  <gazebo reference="beam_support_front_left">
    <material>Gazebo/Blue</material>
  </gazebo>
  <link name="beam_support_back_right">
    <visual>
      <origin rpy="0 0 0" xyz="0 0 0"/>
      <geometry>
        <box size="0.08 0.08 0.32"/>
      </geometry>
      <material name="grey_blue">
        <color rgba="0.3 0.3 0.7 1.0"/>
      </material>
    </visual>
    <collision>
      <origin rpy="0 0 0" xyz="0 0 0"/>
      <geometry>
        <box size="0.08 0.08 0.32"/>
      </geometry>
    </collision>
  </link>
  <joint name="platform_base_beam_support_back_right_joint" type="fixed">
    <parent link="platform_base"/>
    <child link="beam_support_back_right"/>
    <origin rpy="0.0 0.0 0.0" xyz="-0.31                             0.53                             0.275"/>
  </joint>
  <!-- Individual link colouring still needed in Gazebo 2.x -->
  <gazebo reference="beam_support_back_right">
    <material>Gazebo/Blue</material>
  </gazebo>
  <link name="beam_support_back_left">
    <visual>
      <origin rpy="0 0 0" xyz="0 0 0"/>
      <geometry>
        <box size="0.08 0.08 0.32"/>
      </geometry>
      <material name="grey_blue">
        <color rgba="0.3 0.3 0.7 1.0"/>
      </material>
    </visual>
    <collision>
      <origin rpy="0 0 0" xyz="0 0 0"/>
      <geometry>
        <box size="0.08 0.08 0.32"/>
      </geometry>
    </collision>
  </link>
  <joint name="platform_base_beam_support_back_left_joint" type="fixed">
    <parent link="platform_base"/>
    <child link="beam_support_back_left"/>
    <origin rpy="0.0 0.0 0.0" xyz="0.31                             0.53                             0.275"/>
  </joint>
  <!-- Individual link colouring still needed in Gazebo 2.x -->
  <gazebo reference="beam_support_back_left">
    <material>Gazebo/Blue</material>
  </gazebo>
  <link name="beam_support_robot_bottom">
    <visual>
      <origin rpy="0 0 0" xyz="0 0 0"/>
      <geometry>
        <box size="0.08 0.08 0.32"/>
      </geometry>
      <material name="grey_blue">
        <color rgba="0.3 0.3 0.7 1.0"/>
      </material>
    </visual>
    <collision>
      <origin rpy="0 0 0" xyz="0 0 0"/>
      <geometry>
        <box size="0.08 0.08 0.32"/>
      </geometry>
    </collision>
  </link>
  <joint name="platform_base_beam_support_robot_bottom_joint" type="fixed">
    <parent link="platform_base"/>
    <child link="beam_support_robot_bottom"/>
    <origin rpy="0.0 0.0 0.0" xyz="0.0                             0.225                             0.275"/>
  </joint>
  <!-- Individual link colouring still needed in Gazebo 2.x -->
  <gazebo reference="beam_support_robot_bottom">
    <material>Gazebo/Blue</material>
  </gazebo>
  <link name="beam_support_robot_top">
    <visual>
      <origin rpy="0 0 0" xyz="0 0 0"/>
      <geometry>
        <box size="0.08 0.08 0.15"/>
      </geometry>
      <material name="grey_blue">
        <color rgba="0.3 0.3 0.7 1.0"/>
      </material>
    </visual>
    <collision>
      <origin rpy="0 0 0" xyz="0 0 0"/>
      <geometry>
        <box size="0.08 0.08 0.15"/>
      </geometry>
    </collision>
  </link>
  <joint name="platform_base_beam_support_robot_top_joint" type="fixed">
    <parent link="platform_base"/>
    <child link="beam_support_robot_top"/>
    <origin rpy="0.0 0.0 0.0" xyz="0.0                             0.225                             0.55"/>
  </joint>
  <!-- Individual link colouring still needed in Gazebo 2.x -->
  <gazebo reference="beam_support_robot_top">
    <material>Gazebo/Blue</material>
  </gazebo>
  <link name="beam_middle_bottom">
    <visual>
      <origin rpy="0 0 0" xyz="0 0 0"/>
      <geometry>
        <box size="0.08 0.98 0.04"/>
      </geometry>
      <material name="dark_grey">
        <color rgba="0.7 0.7 0.7 1.0"/>
      </material>
    </visual>
    <collision>
      <origin rpy="0 0 0" xyz="0 0 0"/>
      <geometry>
        <box size="0.08 0.98 0.04"/>
      </geometry>
    </collision>
  </link>
  <joint name="platform_base_beam_middle_bottom_joint" type="fixed">
    <parent link="platform_base"/>
    <child link="beam_middle_bottom"/>
    <origin rpy="0.0 0.0 0.0" xyz="0.0 0.0 0.095"/>
  </joint>
  <!-- Individual link colouring still needed in Gazebo 2.x -->
  <gazebo reference="beam_middle_bottom">
    <material>Gazebo/Grey</material>
  </gazebo>
  <link name="beam_middle_top">
    <visual>
      <origin rpy="0 0 0" xyz="0 0 0"/>
      <geometry>
        <box size="0.08 0.98 0.04"/>
      </geometry>
      <material name="dark_grey">
        <color rgba="0.7 0.7 0.7 1.0"/>
      </material>
    </visual>
    <collision>
      <origin rpy="0 0 0" xyz="0 0 0"/>
      <geometry>
        <box size="0.08 0.98 0.04"/>
      </geometry>
    </collision>
  </link>
  <joint name="platform_base_beam_middle_top_joint" type="fixed">
    <parent link="platform_base"/>
    <child link="beam_middle_top"/>
    <origin rpy="0.0 0.0 0.0" xyz="0.0 0.0 0.455"/>
  </joint>
  <!-- Individual link colouring still needed in Gazebo 2.x -->
  <gazebo reference="beam_middle_top">
    <material>Gazebo/Grey</material>
  </gazebo>
  <link name="beam_left_bottom">
    <visual>
      <origin rpy="0 0 0" xyz="0 0 0"/>
      <geometry>
        <box size="0.08 0.98 0.04"/>
      </geometry>
      <material name="dark_grey">
        <color rgba="0.7 0.7 0.7 1.0"/>
      </material>
    </visual>
    <collision>
      <origin rpy="0 0 0" xyz="0 0 0"/>
      <geometry>
        <box size="0.08 0.98 0.04"/>
      </geometry>
    </collision>
  </link>
  <joint name="platform_base_beam_left_bottom_joint" type="fixed">
    <parent link="platform_base"/>
    <child link="beam_left_bottom"/>
    <origin rpy="0.0 0.0 0.0" xyz="0.31                           0.0                           0.095"/>
  </joint>
  <!-- Individual link colouring still needed in Gazebo 2.x -->
  <gazebo reference="beam_left_bottom">
    <material>Gazebo/Grey</material>
  </gazebo>
  <link name="beam_left_top">
    <visual>
      <origin rpy="0 0 0" xyz="0 0 0"/>
      <geometry>
        <box size="0.08 0.98 0.04"/>
      </geometry>
      <material name="dark_grey">
        <color rgba="0.7 0.7 0.7 1.0"/>
      </material>
    </visual>
    <collision>
      <origin rpy="0 0 0" xyz="0 0 0"/>
      <geometry>
        <box size="0.08 0.98 0.04"/>
      </geometry>
    </collision>
  </link>
  <joint name="platform_base_beam_left_top_joint" type="fixed">
    <parent link="platform_base"/>
    <child link="beam_left_top"/>
    <origin rpy="0.0 0.0 0.0" xyz="0.31                           0.0                           0.455"/>
  </joint>
  <!-- Individual link colouring still needed in Gazebo 2.x -->
  <gazebo reference="beam_left_top">
    <material>Gazebo/Grey</material>
  </gazebo>
  <link name="beam_right_bottom">
    <visual>
      <origin rpy="0 0 0" xyz="0 0 0"/>
      <geometry>
        <box size="0.08 0.98 0.04"/>
      </geometry>
      <material name="dark_grey">
        <color rgba="0.7 0.7 0.7 1.0"/>
      </material>
    </visual>
    <collision>
      <origin rpy="0 0 0" xyz="0 0 0"/>
      <geometry>
        <box size="0.08 0.98 0.04"/>
      </geometry>
    </collision>
  </link>
  <joint name="platform_base_beam_right_bottom_joint" type="fixed">
    <parent link="platform_base"/>
    <child link="beam_right_bottom"/>
    <origin rpy="0.0 0.0 0.0" xyz="-0.31                           0.0                           0.095"/>
  </joint>
  <!-- Individual link colouring still needed in Gazebo 2.x -->
  <gazebo reference="beam_right_bottom">
    <material>Gazebo/Grey</material>
  </gazebo>
  <link name="beam_right_top">
    <visual>
      <origin rpy="0 0 0" xyz="0 0 0"/>
      <geometry>
        <box size="0.08 0.98 0.04"/>
      </geometry>
      <material name="dark_grey">
        <color rgba="0.7 0.7 0.7 1.0"/>
      </material>
    </visual>
    <collision>
      <origin rpy="0 0 0" xyz="0 0 0"/>
      <geometry>
        <box size="0.08 0.98 0.04"/>
      </geometry>
    </collision>
  </link>
  <joint name="platform_base_beam_right_top_joint" type="fixed">
    <parent link="platform_base"/>
    <child link="beam_right_top"/>
    <origin rpy="0.0 0.0 0.0" xyz="-0.31                           0.0                           0.455"/>
  </joint>
  <!-- Individual link colouring still needed in Gazebo 2.x -->
  <gazebo reference="beam_right_top">
    <material>Gazebo/Grey</material>
  </gazebo>
  <link name="beam_front_bottom">
    <visual>
      <origin rpy="0 0 0" xyz="0 0 0"/>
      <geometry>
        <box size="0.7 0.08 0.04"/>
      </geometry>
      <material name="dark_grey">
        <color rgba="0.7 0.7 0.7 1.0"/>
      </material>
    </visual>
    <collision>
      <origin rpy="0 0 0" xyz="0 0 0"/>
      <geometry>
        <box size="0.7 0.08 0.04"/>
      </geometry>
    </collision>
  </link>
  <joint name="platform_base_beam_front_bottom_joint" type="fixed">
    <parent link="platform_base"/>
    <child link="beam_front_bottom"/>
    <origin rpy="0.0 0.0 0.0" xyz="0.0                          -0.53                           0.095"/>
  </joint>
  <!-- Individual link colouring still needed in Gazebo 2.x -->
  <gazebo reference="beam_front_bottom">
    <material>Gazebo/Grey</material>
  </gazebo>
  <link name="beam_front_top">
    <visual>
      <origin rpy="0 0 0" xyz="0 0 0"/>
      <geometry>
        <box size="0.7 0.08 0.04"/>
      </geometry>
      <material name="dark_grey">
        <color rgba="0.7 0.7 0.7 1.0"/>
      </material>
    </visual>
    <collision>
      <origin rpy="0 0 0" xyz="0 0 0"/>
      <geometry>
        <box size="0.7 0.08 0.04"/>
      </geometry>
    </collision>
  </link>
  <joint name="platform_base_beam_front_top_joint" type="fixed">
    <parent link="platform_base"/>
    <child link="beam_front_top"/>
    <origin rpy="0.0 0.0 0.0" xyz="0.0                          -0.53                           0.455"/>
  </joint>
  <!-- Individual link colouring still needed in Gazebo 2.x -->
  <gazebo reference="beam_front_top">
    <material>Gazebo/Grey</material>
  </gazebo>
  <link name="beam_back_bottom">
    <visual>
      <origin rpy="0 0 0" xyz="0 0 0"/>
      <geometry>
        <box size="0.7 0.08 0.04"/>
      </geometry>
      <material name="dark_grey">
        <color rgba="0.7 0.7 0.7 1.0"/>
      </material>
    </visual>
    <collision>
      <origin rpy="0 0 0" xyz="0 0 0"/>
      <geometry>
        <box size="0.7 0.08 0.04"/>
      </geometry>
    </collision>
  </link>
  <joint name="platform_base_beam_back_bottom_joint" type="fixed">
    <parent link="platform_base"/>
    <child link="beam_back_bottom"/>
    <origin rpy="0.0 0.0 0.0" xyz="0.0                          0.53                           0.095"/>
  </joint>
  <!-- Individual link colouring still needed in Gazebo 2.x -->
  <gazebo reference="beam_back_bottom">
    <material>Gazebo/Grey</material>
  </gazebo>
  <link name="beam_back_top">
    <visual>
      <origin rpy="0 0 0" xyz="0 0 0"/>
      <geometry>
        <box size="0.7 0.08 0.04"/>
      </geometry>
      <material name="dark_grey">
        <color rgba="0.7 0.7 0.7 1.0"/>
      </material>
    </visual>
    <collision>
      <origin rpy="0 0 0" xyz="0 0 0"/>
      <geometry>
        <box size="0.7 0.08 0.04"/>
      </geometry>
    </collision>
  </link>
  <joint name="platform_base_beam_back_top_joint" type="fixed">
    <parent link="platform_base"/>
    <child link="beam_back_top"/>
    <origin rpy="0.0 0.0 0.0" xyz="0.0                          0.53                           0.455"/>
  </joint>
  <!-- Individual link colouring still needed in Gazebo 2.x -->
  <gazebo reference="beam_back_top">
    <material>Gazebo/Grey</material>
  </gazebo>
  <link name="beam_connect_left_bottom">
    <visual>
      <origin rpy="0 0 0" xyz="0 0 0"/>
      <geometry>
        <box size="0.23 0.08 0.04"/>
      </geometry>
      <material name="dark_grey">
        <color rgba="0.7 0.7 0.7 1.0"/>
      </material>
    </visual>
    <collision>
      <origin rpy="0 0 0" xyz="0 0 0"/>
      <geometry>
        <box size="0.23 0.08 0.04"/>
      </geometry>
    </collision>
  </link>
  <joint name="platform_base_beam_connect_left_bottom_joint" type="fixed">
    <parent link="platform_base"/>
    <child link="beam_connect_left_bottom"/>
    <origin rpy="0.0 0.0 0.0" xyz="0.155                          0.0                          0.095"/>
  </joint>
  <!-- Individual link colouring still needed in Gazebo 2.x -->
  <gazebo reference="beam_connect_left_bottom">
    <material>Gazebo/Grey</material>
  </gazebo>
  <link name="beam_connect_left_top">
    <visual>
      <origin rpy="0 0 0" xyz="0 0 0"/>
      <geometry>
        <box size="0.23 0.08 0.04"/>
      </geometry>
      <material name="dark_grey">
        <color rgba="0.7 0.7 0.7 1.0"/>
      </material>
    </visual>
    <collision>
      <origin rpy="0 0 0" xyz="0 0 0"/>
      <geometry>
        <box size="0.23 0.08 0.04"/>
      </geometry>
    </collision>
  </link>
  <joint name="platform_base_beam_connect_left_top_joint" type="fixed">
    <parent link="platform_base"/>
    <child link="beam_connect_left_top"/>
    <origin rpy="0.0 0.0 0.0" xyz="0.155                          0.0                          0.455"/>
  </joint>
  <!-- Individual link colouring still needed in Gazebo 2.x -->
  <gazebo reference="beam_connect_left_top">
    <material>Gazebo/Grey</material>
  </gazebo>
  <link name="beam_connect_right_bottom">
    <visual>
      <origin rpy="0 0 0" xyz="0 0 0"/>
      <geometry>
        <box size="0.23 0.08 0.04"/>
      </geometry>
      <material name="dark_grey">
        <color rgba="0.7 0.7 0.7 1.0"/>
      </material>
    </visual>
    <collision>
      <origin rpy="0 0 0" xyz="0 0 0"/>
      <geometry>
        <box size="0.23 0.08 0.04"/>
      </geometry>
    </collision>
  </link>
  <joint name="platform_base_beam_connect_right_bottom_joint" type="fixed">
    <parent link="platform_base"/>
    <child link="beam_connect_right_bottom"/>
    <origin rpy="0.0 0.0 0.0" xyz="-0.155                          0.0                          0.095"/>
  </joint>
  <!-- Individual link colouring still needed in Gazebo 2.x -->
  <gazebo reference="beam_connect_right_bottom">
    <material>Gazebo/Grey</material>
  </gazebo>
  <link name="beam_connect_right_top">
    <visual>
      <origin rpy="0 0 0" xyz="0 0 0"/>
      <geometry>
        <box size="0.23 0.08 0.04"/>
      </geometry>
      <material name="dark_grey">
        <color rgba="0.7 0.7 0.7 1.0"/>
      </material>
    </visual>
    <collision>
      <origin rpy="0 0 0" xyz="0 0 0"/>
      <geometry>
        <box size="0.23 0.08 0.04"/>
      </geometry>
    </collision>
  </link>
  <joint name="platform_base_beam_connect_right_top_joint" type="fixed">
    <parent link="platform_base"/>
    <child link="beam_connect_right_top"/>
    <origin rpy="0.0 0.0 0.0" xyz="-0.155                          0.0                          0.455"/>
  </joint>
  <!-- Individual link colouring still needed in Gazebo 2.x -->
  <gazebo reference="beam_connect_right_top">
    <material>Gazebo/Grey</material>
  </gazebo>

  <link name="operation_surface">
    <visual>
      <origin rpy="0 0 0" xyz="0 0 -0.0125"/>
      <geometry>
        <box size="0.7 0.6 0.025"/>
      </geometry>
      <material name="grey_yellow">
        <color rgba="0.7 0.7 0.2 1.0"/>
      </material>
    </visual>
    <collision>
      <origin rpy="0 0 0" xyz="0 0 -0.0125"/>
      <geometry>
        <box size="0.7 0.6 0.025"/>
      </geometry>
    </collision>
  </link>
  <joint name="platform_base_operation_surface_joint" type="fixed">
    <parent link="platform_base"/>
    <child link="operation_surface"/>
    <origin rpy="0.0 0.0 0.0" xyz="0.0                   -0.27                   0.5"/>
  </joint>
  <!-- Individual link colouring still needed in Gazebo 2.x -->
  <gazebo reference="operation_surface">
    <material>Gazebo/Wood</material>
  </gazebo>
  <link name="robot_install_plate">
    <visual>
      <origin rpy="0 0 0" xyz="0 0 0"/>
      <geometry>
        <cylinder length="0.015" radius="0.075"/>
      </geometry>
      <material name="dark_black">
        <color rgba="0.1 0.1 0.1 1.0"/>
      </material>
    </visual>
    <collision>
      <origin rpy="0 0 0" xyz="0 0 0"/>
      <geometry>
        <cylinder length="0.015" radius="0.075"/>
      </geometry>
    </collision>
  </link>
  <joint name="platform_base_robot_install_plate_joint" type="fixed">
    <parent link="beam_support_robot_top"/>
    <child link="robot_install_plate"/>
    <origin rpy="0.0 0.0 0.0" xyz="0.0                   0.0                   0.0825"/>
  </joint>
  <!-- Individual link colouring still needed in Gazebo 2.x -->
  <gazebo reference="robot_install_plate">
    <material>Gazebo/FlatBlack</material>
  </gazebo>
  <!-- measured from model -->
  <!--property name="shoulder_height" value="0.089159" /-->
  <!--property name="shoulder_offset" value="0.13585" /-->
  <!-- shoulder_offset - elbow_offset + wrist_1_length = 0.10915 -->
  <!--property name="upper_arm_length" value="0.42500" /-->
  <!--property name="elbow_offset" value="0.1197" /-->
  <!-- CAD measured -->
  <!--property name="forearm_length" value="0.39225" /-->
  <!--property name="wrist_1_length" value="0.093" /-->
  <!-- CAD measured -->
  <!--property name="wrist_2_length" value="0.09465" /-->
  <!-- In CAD this distance is 0.930, but in the spec it is 0.09465 -->
  <!--property name="wrist_3_length" value="0.0823" /-->
  <!-- manually measured -->
  <link name="base_link">
    <visual>
      <geometry>
        <mesh filename="package://ur_description/meshes/ur5/visual/base.dae"/>
      </geometry>
      <material name="LightGrey">
        <color rgba="0.7 0.7 0.7 1.0"/>
      </material>
    </visual>
    <collision>
      <geometry>
        <mesh filename="package://ur_description/meshes/ur5/collision/base.stl"/>
      </geometry>
    </collision>
    <inertial>
      <mass value="4.0"/>
      <origin rpy="0 0 0" xyz="0.0 0.0 0.0"/>
      <inertia ixx="0.00443333156" ixy="0.0" ixz="0.0" iyy="0.00443333156" iyz="0.0" izz="0.0072"/>
    </inertial>
  </link>
  <joint name="shoulder_pan_joint" type="revolute">
    <parent link="base_link"/>
    <child link="shoulder_link"/>
    <origin rpy="0.0 0.0 0.0" xyz="0.0 0.0 0.089159"/>
    <axis xyz="0 0 1"/>
    <limit effort="150.0" lower="-6.28318530718" upper="6.28318530718" velocity="3.15"/>
    <dynamics damping="0.0" friction="0.0"/>
  </joint>
  <link name="shoulder_link">
    <visual>
      <geometry>
        <mesh filename="package://ur_description/meshes/ur5/visual/shoulder.dae"/>
      </geometry>
      <material name="LightGrey">
        <color rgba="0.7 0.7 0.7 1.0"/>
      </material>
    </visual>
    <collision>
      <geometry>
        <mesh filename="package://ur_description/meshes/ur5/collision/shoulder.stl"/>
      </geometry>
    </collision>
    <inertial>
      <mass value="3.7"/>
      <origin rpy="0 0 0" xyz="0.0 0.0 0.0"/>
      <inertia ixx="0.010267495893" ixy="0.0" ixz="0.0" iyy="0.010267495893" iyz="0.0" izz="0.00666"/>
    </inertial>
  </link>
  <joint name="shoulder_lift_joint" type="revolute">
    <parent link="shoulder_link"/>
    <child link="upper_arm_link"/>
    <origin rpy="0.0 1.57079632679 0.0" xyz="0.0 0.13585 0.0"/>
    <axis xyz="0 1 0"/>
    <limit effort="150.0" lower="-6.28318530718" upper="6.28318530718" velocity="3.15"/>
    <dynamics damping="0.0" friction="0.0"/>
  </joint>
  <link name="upper_arm_link">
    <visual>
      <geometry>
        <mesh filename="package://ur_description/meshes/ur5/visual/upperarm.dae"/>
      </geometry>
      <material name="LightGrey">
        <color rgba="0.7 0.7 0.7 1.0"/>
      </material>
    </visual>
    <collision>
      <geometry>
        <mesh filename="package://ur_description/meshes/ur5/collision/upperarm.stl"/>
      </geometry>
    </collision>
    <inertial>
      <mass value="8.393"/>
      <origin rpy="0 0 0" xyz="0.0 0.0 0.28"/>
      <inertia ixx="0.22689067591" ixy="0.0" ixz="0.0" iyy="0.22689067591" iyz="0.0" izz="0.0151074"/>
    </inertial>
  </link>
  <joint name="elbow_joint" type="revolute">
    <parent link="upper_arm_link"/>
    <child link="forearm_link"/>
    <origin rpy="0.0 0.0 0.0" xyz="0.0 -0.1197 0.425"/>
    <axis xyz="0 1 0"/>
    <limit effort="150.0" lower="-3.14159265359" upper="3.14159265359" velocity="3.15"/>
    <dynamics damping="0.0" friction="0.0"/>
  </joint>
  <link name="forearm_link">
    <visual>
      <geometry>
        <mesh filename="package://ur_description/meshes/ur5/visual/forearm.dae"/>
      </geometry>
      <material name="LightGrey">
        <color rgba="0.7 0.7 0.7 1.0"/>
      </material>
    </visual>
    <collision>
      <geometry>
        <mesh filename="package://ur_description/meshes/ur5/collision/forearm.stl"/>
      </geometry>
    </collision>
    <inertial>
      <mass value="2.275"/>
      <origin rpy="0 0 0" xyz="0.0 0.0 0.25"/>
      <inertia ixx="0.049443313556" ixy="0.0" ixz="0.0" iyy="0.049443313556" iyz="0.0" izz="0.004095"/>
    </inertial>
  </link>
  <joint name="wrist_1_joint" type="revolute">
    <parent link="forearm_link"/>
    <child link="wrist_1_link"/>
    <origin rpy="0.0 1.57079632679 0.0" xyz="0.0 0.0 0.39225"/>
    <axis xyz="0 1 0"/>
    <limit effort="28.0" lower="-6.28318530718" upper="6.28318530718" velocity="3.2"/>
    <dynamics damping="0.0" friction="0.0"/>
  </joint>
  <link name="wrist_1_link">
    <visual>
      <geometry>
        <mesh filename="package://ur_description/meshes/ur5/visual/wrist1.dae"/>
      </geometry>
      <material name="LightGrey">
        <color rgba="0.7 0.7 0.7 1.0"/>
      </material>
    </visual>
    <collision>
      <geometry>
        <mesh filename="package://ur_description/meshes/ur5/collision/wrist1.stl"/>
      </geometry>
    </collision>
    <inertial>
      <mass value="1.219"/>
      <origin rpy="0 0 0" xyz="0.0 0.0 0.0"/>
      <inertia ixx="0.111172755531" ixy="0.0" ixz="0.0" iyy="0.111172755531" iyz="0.0" izz="0.21942"/>
    </inertial>
  </link>
  <joint name="wrist_2_joint" type="revolute">
    <parent link="wrist_1_link"/>
    <child link="wrist_2_link"/>
    <origin rpy="0.0 0.0 0.0" xyz="0.0 0.093 0.0"/>
    <axis xyz="0 0 1"/>
    <limit effort="28.0" lower="-6.28318530718" upper="6.28318530718" velocity="3.2"/>
    <dynamics damping="0.0" friction="0.0"/>
  </joint>
  <link name="wrist_2_link">
    <visual>
      <geometry>
        <mesh filename="package://ur_description/meshes/ur5/visual/wrist2.dae"/>
      </geometry>
      <material name="LightGrey">
        <color rgba="0.7 0.7 0.7 1.0"/>
      </material>
    </visual>
    <collision>
      <geometry>
        <mesh filename="package://ur_description/meshes/ur5/collision/wrist2.stl"/>
      </geometry>
    </collision>
    <inertial>
      <mass value="1.219"/>
      <origin rpy="0 0 0" xyz="0.0 0.0 0.0"/>
      <inertia ixx="0.111172755531" ixy="0.0" ixz="0.0" iyy="0.111172755531" iyz="0.0" izz="0.21942"/>
    </inertial>
  </link>
  <joint name="wrist_3_joint" type="revolute">
    <parent link="wrist_2_link"/>
    <child link="wrist_3_link"/>
    <origin rpy="0.0 0.0 0.0" xyz="0.0 0.0 0.09465"/>
    <axis xyz="0 1 0"/>
    <limit effort="28.0" lower="-6.28318530718" upper="6.28318530718" velocity="3.2"/>
    <dynamics damping="0.0" friction="0.0"/>
  </joint>
  <link name="wrist_3_link">
    <visual>
      <geometry>
        <mesh filename="package://ur_description/meshes/ur5/visual/wrist3.dae"/>
      </geometry>
      <material name="LightGrey">
        <color rgba="0.7 0.7 0.7 1.0"/>
      </material>
    </visual>
    <collision>
      <geometry>
        <mesh filename="package://ur_description/meshes/ur5/collision/wrist3.stl"/>
      </geometry>
    </collision>
    <inertial>
      <mass value="0.1879"/>
      <origin rpy="0 0 0" xyz="0.0 0.0 0.0"/>
      <inertia ixx="0.0171364731454" ixy="0.0" ixz="0.0" iyy="0.0171364731454" iyz="0.0" izz="0.033822"/>
    </inertial>
  </link>
  <joint name="ee_fixed_joint" type="fixed">
    <parent link="wrist_3_link"/>
    <child link="ee_link"/>
    <origin rpy="0.0 0.0 1.57079632679" xyz="0.0 0.0823 0.0"/>
  </joint>
  <link name="ee_link">
    <collision>
      <geometry>
        <box size="0.01 0.01 0.01"/>
      </geometry>
      <origin rpy="0 0 0" xyz="-0.01 0 0"/>
    </collision>
  </link>
  <transmission name="shoulder_pan_trans">
    <type>transmission_interface/SimpleTransmission</type>
    <joint name="shoulder_pan_joint">
      <hardwareInterface>hardware_interface/PositionJointInterface</hardwareInterface>
    </joint>
    <actuator name="shoulder_pan_motor">
      <mechanicalReduction>1</mechanicalReduction>
    </actuator>
  </transmission>
  <transmission name="shoulder_lift_trans">
    <type>transmission_interface/SimpleTransmission</type>
    <joint name="shoulder_lift_joint">
      <hardwareInterface>hardware_interface/PositionJointInterface</hardwareInterface>
    </joint>
    <actuator name="shoulder_lift_motor">
      <mechanicalReduction>1</mechanicalReduction>
    </actuator>
  </transmission>
  <transmission name="elbow_trans">
    <type>transmission_interface/SimpleTransmission</type>
    <joint name="elbow_joint">
      <hardwareInterface>hardware_interface/PositionJointInterface</hardwareInterface>
    </joint>
    <actuator name="elbow_motor">
      <mechanicalReduction>1</mechanicalReduction>
    </actuator>
  </transmission>
  <transmission name="wrist_1_trans">
    <type>transmission_interface/SimpleTransmission</type>
    <joint name="wrist_1_joint">
      <hardwareInterface>hardware_interface/PositionJointInterface</hardwareInterface>
    </joint>
    <actuator name="wrist_1_motor">
      <mechanicalReduction>1</mechanicalReduction>
    </actuator>
  </transmission>
  <transmission name="wrist_2_trans">
    <type>transmission_interface/SimpleTransmission</type>
    <joint name="wrist_2_joint">
      <hardwareInterface>hardware_interface/PositionJointInterface</hardwareInterface>
    </joint>
    <actuator name="wrist_2_motor">
      <mechanicalReduction>1</mechanicalReduction>
    </actuator>
  </transmission>
  <transmission name="wrist_3_trans">
    <type>transmission_interface/SimpleTransmission</type>
    <joint name="wrist_3_joint">
      <hardwareInterface>hardware_interface/PositionJointInterface</hardwareInterface>
    </joint>
    <actuator name="wrist_3_motor">
      <mechanicalReduction>1</mechanicalReduction>
    </actuator>
  </transmission>
  <gazebo reference="shoulder_link">
    <selfCollide>true</selfCollide>
  </gazebo>
  <gazebo reference="upper_arm_link">
    <selfCollide>true</selfCollide>
  </gazebo>
  <gazebo reference="forearm_link">
    <selfCollide>true</selfCollide>
  </gazebo>
  <gazebo reference="wrist_1_link">
    <selfCollide>true</selfCollide>
  </gazebo>
  <gazebo reference="wrist_3_link">
    <selfCollide>true</selfCollide>
  </gazebo>
  <gazebo reference="wrist_2_link">
    <selfCollide>true</selfCollide>
  </gazebo>
  <gazebo reference="ee_link">
    <selfCollide>true</selfCollide>
  </gazebo>
  <!-- ROS base_link to UR 'Base' Coordinates transform -->
  <link name="base"/>
  <joint name="base_link-base_fixed_joint" type="fixed">
    <!-- NOTE: this rotation is only needed as long as base_link itself is
                 not corrected wrt the real robot (ie: rotated over 180
                 degrees)
      -->
    <origin rpy="0 0 -3.14159265359" xyz="0 0 0"/>
    <parent link="base_link"/>
    <child link="base"/>
  </joint>
  <!-- Frame coincident with all-zeros TCP on UR controller -->
  <link name="tool0"/>
  <joint name="wrist_3_link-tool0_fixed_joint" type="fixed">
    <origin rpy="-1.57079632679 0 0" xyz="0 0.0823 0"/>
    <parent link="wrist_3_link"/>
    <child link="tool0"/>
  </joint>
  <gazebo reference="hitbot_base">
    <material>Gazebo/Black</material>
    <mu1>0.9</mu1>
    <mu2>0.9</mu2>
  </gazebo>
  <gazebo reference="hitbot_mask">
    <mu1>0.9</mu1>
    <mu2>0.9</mu2>
  </gazebo>
  <gazebo reference="hitbot_finger0">
    <material>Gazebo/Grey</material>
    <mu1>0.9</mu1>
    <mu2>0.9</mu2>
  </gazebo>
  <gazebo reference="hitbot_finger1">
    <material>Gazebo/Grey</material>
    <mu1>0.9</mu1>
    <mu2>0.9</mu2>
  </gazebo>
  <transmission name="hitbot_finger_joint1_trans">
    <type>transmission_interface/SimpleTransmission</type>
    <joint name="hitbot_base_finger0_joint">
      <hardwareInterface>hardware_interface/PositionJointInterface</hardwareInterface>
    </joint>
    <actuator name="hitbot_finger_joint1_motor">
      <mechanicalReduction>1</mechanicalReduction>
      <hardwareInterface>hardware_interface/PositionJointInterface</hardwareInterface>
    </actuator>
  </transmission>
  <transmission name="hitbot_finger_joint2_trans">
    <type>transmission_interface/SimpleTransmission</type>
    <joint name="hitbot_base_finger1_joint">
      <hardwareInterface>hardware_interface/PositionJointInterface</hardwareInterface>
    </joint>
    <actuator name="hitbot_finger_joint2_motor">
      <mechanicalReduction>1</mechanicalReduction>
      <hardwareInterface>hardware_interface/PositionJointInterface</hardwareInterface>
    </actuator>
  </transmission>
  <!-- Gazebo grasping plugin -->
  <gazebo>
    <gripper name="gazebo_gripper">
      <grasp_check>
        <attach_steps>2</attach_steps>
        <!-- default: 20 -->
        <detach_steps>2</detach_steps>
        <!-- default: 40 -->
        <min_contact_count>2</min_contact_count>
      </grasp_check>
      <gripper_link>hitbot_finger0</gripper_link>
      <gripper_link>hitbot_finger1</gripper_link>
      <palm_link>hitbot_base</palm_link>
    </gripper>
  </gazebo>
  <!-- base -->
  <link name="hitbot_base">
    <inertial>
      <mass value="0.1"/>
      <origin rpy="0 0 0" xyz="0 0.0015244 0.0275912"/>
      <inertia ixx="3.01220925051e-05" ixy="0.0" ixz="0.0" iyy="2.95873808038e-05" iyz="0.0" izz="6.95125211657e-06"/>
    </inertial>
    <visual>
      <geometry>
        <mesh filename="package://handson_description/meshes/base.stl"/>
      </geometry>
      <material name="steel">
        <color rgba="0.2 0.2 0.2 1"/>
      </material>
    </visual>
    <collision>
      <geometry>
        <mesh filename="package://handson_description/meshes/base.stl"/>
      </geometry>
    </collision>
  </link>
  <!-- mask -->
  <link name="hitbot_mask">
    <inertial>
      <mass value="0.1"/>
      <origin rpy="0 0 0" xyz="0 0.0015244 0.0275912"/>
      <inertia ixx="3.01220925051e-05" ixy="0.0" ixz="0.0" iyy="2.95873808038e-05" iyz="0.0" izz="6.95125211657e-06"/>
    </inertial>
    <visual>
      <geometry>
        <mesh filename="package://handson_description/meshes/mask.stl"/>
      </geometry>
      <material name="plastic">
        <color rgba="0.95 0.95 0.95 1"/>
      </material>
    </visual>
    <collision>
      <geometry>
        <mesh filename="package://handson_description/meshes/mask.stl"/>
      </geometry>
    </collision>
  </link>
  <joint name="hitbot_base_mask_joint" type="fixed">
    <origin rpy="0 0 0" xyz="0 0 0.006"/>
    <parent link="hitbot_base"/>
    <child link="hitbot_mask"/>
  </joint>
  <!-- finger 0 -->
  <link name="hitbot_finger0">
    <inertial>
      <mass value="0.1"/>
      <origin rpy="0 0 0" xyz="0 0.0145644 0.0227941"/>
      <inertia ixx="3.01220925051e-05" ixy="0.0" ixz="0.0" iyy="2.95873808038e-05" iyz="0.0" izz="6.95125211657e-06"/>
    </inertial>
    <visual>
      <geometry>
        <mesh filename="package://handson_description/meshes/finger.stl"/>
      </geometry>
      <material name="aluminum">
        <color rgba="0.5 0.5 0.5 1"/>
      </material>
    </visual>
    <collision>
      <geometry>
        <mesh filename="package://handson_description/meshes/finger.stl"/>
      </geometry>
    </collision>
  </link>
  <joint name="hitbot_base_finger0_joint" type="prismatic">
    <origin rpy="0 0 0" xyz="0 -0.010 0.114"/>
    <parent link="hitbot_base"/>
    <child link="hitbot_finger0"/>
    <axis xyz="0 1 0"/>
    <limit effort="1000" lower="-0.010" upper="0" velocity="0.01"/>
  </joint>
  <!-- finger 0 tip -->
  <link name="hitbot_finger0_tip">
    <inertial>
      <mass value="0.1"/>
      <origin rpy="0 0 0" xyz="0 0.0145644 0.0227941"/>
      <inertia ixx="3.01220925051e-05" ixy="0.0" ixz="0.0" iyy="2.95873808038e-05" iyz="0.0" izz="6.95125211657e-06"/>
    </inertial>
    <visual>
      <geometry>
        <mesh filename="package://handson_description/meshes/finger_tip.stl"/>
      </geometry>
      <material name="steel">
        <color rgba="0.2 0.2 0.2 1"/>
      </material>
    </visual>
    <collision>
      <geometry>
        <mesh filename="package://handson_description/meshes/finger_tip.stl"/>
      </geometry>
    </collision>
  </link>
  <joint name="hitbot_finger0_tip_joint" type="fixed">
    <origin rpy="-1.57079632679 0 3.14159265359" xyz="0 0 0.01"/>
    <parent link="hitbot_finger0"/>
    <child link="hitbot_finger0_tip"/>
  </joint>
  <!-- finger 1 -->
  <link name="hitbot_finger1">
    <inertial>
      <mass value="0.1"/>
      <origin rpy="0 0 3.14159265359" xyz="0 0.0145644 0.0227941"/>
      <inertia ixx="3.01220925051e-05" ixy="0.0" ixz="0.0" iyy="2.95873808038e-05" iyz="0.0" izz="6.95125211657e-06"/>
    </inertial>
    <visual>
      <geometry>
        <mesh filename="package://handson_description/meshes/finger.stl"/>
      </geometry>
      <material name="aluminum">
        <color rgba="0.5 0.5 0.5 1"/>
      </material>
    </visual>
    <collision>
      <geometry>
        <mesh filename="package://handson_description/meshes/finger.stl"/>
      </geometry>
    </collision>
  </link>
  <joint name="hitbot_base_finger1_joint" type="prismatic">
    <origin rpy="0 0 0" xyz="0 0.004 0.114"/>
    <parent link="hitbot_base"/>
    <child link="hitbot_finger1"/>
    <axis xyz="0 1 0"/>
    <limit effort="1000" lower="0" upper="0.010" velocity="0.01"/>
  </joint>
  <!-- finger 0 tip -->
  <link name="hitbot_finger1_tip">
    <inertial>
      <mass value="0.1"/>
      <origin rpy="0 0 0" xyz="0 0.0145644 0.0227941"/>
      <inertia ixx="3.01220925051e-05" ixy="0.0" ixz="0.0" iyy="2.95873808038e-05" iyz="0.0" izz="6.95125211657e-06"/>
    </inertial>
    <visual>
      <geometry>
        <mesh filename="package://handson_description/meshes/finger_tip.stl"/>
      </geometry>
      <material name="steel">
        <color rgba="0.2 0.2 0.2 1"/>
      </material>
    </visual>
    <collision>
      <geometry>
        <mesh filename="package://handson_description/meshes/finger_tip.stl"/>
      </geometry>
    </collision>
  </link>
  <joint name="hitbot_finger1_tip_joint" type="fixed">
    <origin rpy="-1.57079632679 0 0" xyz="0 0.0055 0.01"/>
    <parent link="hitbot_finger1"/>
    <child link="hitbot_finger1_tip"/>
  </joint>
  <!-- world link -->
  <link name="world"/>
  <joint name="world_platform_joint" type="fixed">
    <parent link="world"/>
    <child link="platform_base"/>
    <origin rpy="0.0 0.0 0.0" xyz="0.0 0.0 0.0"/>
  </joint>
  <joint name="platform_base_link_joint" type="fixed">
    <parent link="robot_install_plate"/>
    <child link="base_link"/>
    <origin rpy="0.0 0.0 3.14159265359" xyz="0.0 0.0 0.0075"/>
  </joint>
  <joint name="tool0_hitbot_joint" type="fixed">
    <parent link="tool0"/>
    <child link="hitbot_base"/>
    <origin rpy="0.0 0.0 0.785398163397" xyz="0.0 0.0 0.0"/>
  </joint>
</robot>

